<mujoco model="arm">
  <compiler angle="radian"/>

  <asset>
    <mesh name="base_link" content_type="model/stl" file="base_link.STL"/>
    <mesh name="arm_link1" content_type="model/stl" file="arm_link1.STL"/>
    <mesh name="arm_link2" content_type="model/stl" file="arm_link2.STL"/>
    <mesh name="wrist_link1" content_type="model/stl" file="wrist_link1.STL"/>
    <mesh name="wrist_link2" content_type="model/stl" file="wrist_link2.STL"/>
    <mesh name="wrist_link3" content_type="model/stl" file="wrist_link3.STL"/>
  </asset>

  <worldbody>
    <geom type="mesh" rgba="0.79216 0.81961 0.93333 1" mesh="base_link"/>
    <body name="arm_link1" pos="0 0 0.011635" quat="0.702775 0.48693 0.512738 0.0781371">
      <inertial pos="-0.036656 0.24877 0.0017121" quat="0.503599 0.498181 -0.494722 0.503443" mass="0.69727" diaginertia="0.010952 0.0107561 0.000718225"/>
      <joint name="joint0" pos="0 0 0" axis="0.644589 -0.764529 0" range="-1.57 1.57"/>
      <geom type="mesh" rgba="0.79216 0.81961 0.93333 1" mesh="arm_link1"/>
      <body name="arm_link2" pos="-0.1546 0.18337 0" quat="0.811752 0 0 -0.584002">
        <inertial pos="-0.1803 0.28553 -0.0137" quat="0.442075 0.536052 -0.553438 0.459265" mass="0.44856" diaginertia="0.00180007 0.00175566 0.000374045"/>
        <joint name="joint1" pos="0 0 0" axis="0.92979 0.36809 0" range="-2.36 2.36"/>
        <geom type="mesh" rgba="0.79216 0.81961 0.93333 1" mesh="arm_link2"/>
        <body name="wrist_link1" pos="0.061947 0.024524 0" quat="0.707105 0 0.707108 0">
          <inertial pos="-0.012917 0.39657 -0.2425" quat="0.502285 0.497703 -0.497721 0.502271" mass="0.28916" diaginertia="0.00110567 0.0010542 0.000321195"/>
          <joint name="joint2" pos="0 0 0" axis="0 0.36809 0.92979" range="-3.14 3.14"/>
          <geom type="mesh" rgba="0.79216 0.81961 0.93333 1" mesh="wrist_link1"/>
          <body name="wrist_link2" pos="0 -0.0042228 -0.010667" quat="0.433338 -0.558764 -0.433342 0.558764">
            <inertial pos="0.56466 0.10603 0.0069794" quat="0.500171 0.499829 0.499829 0.500171" mass="0.34435" diaginertia="0.00063583 0.00062808 0.00013834"/>
            <joint name="joint3" pos="0 0 0" axis="0.12512 -0.992142 0" range="-1.57 1.57"/>
            <geom type="mesh" rgba="0.79216 0.81961 0.93333 1" mesh="wrist_link2"/>
            <body name="wrist_link3" pos="0.0032086 -0.025443 0" quat="-0.0156296 0.706934 0.0156271 0.706934">
              <inertial pos="0.0051806 -0.13286 0.69835" quat="0.706531 -0.0264204 -0.0254876 0.706729" mass="0.17519" diaginertia="5.8965e-05 4.87725e-05 3.49224e-05"/>
              <joint name="joint4" pos="0 0 0" axis="0 0.991932 0.12677" range="-2.36 2.36"/>
              <geom type="mesh" rgba="0.79216 0.81961 0.93333 1" mesh="wrist_link3"/>
            </body>
          </body>
        </body>
      </body>
    </body>
  </worldbody>
</mujoco>
