<?xml version="1.0" encoding="utf-8"?>
<!-- This URDF was automatically created by SolidWorks to URDF Exporter! Originally created by Stephen Brawner (brawner@gmail.com) 
     Commit Version: 1.6.0-4-g7f85cfe  Build Version: 1.6.7995.38578
     For more information, please see http://wiki.ros.org/sw_urdf_exporter -->
<robot
  name="arm">
  <link
    name="base_link">
    <inertial>
      <origin
        xyz="0.0057948 0.044245 0.0043726"
        rpy="0 0 0" />
      <mass
        value="0.63881" />
      <inertia
        ixx="0.0014518"
        ixy="2.1581E-05"
        ixz="-7.6039E-05"
        iyy="0.0017544"
        iyz="1.5819E-05"
        izz="0.0014944" />
    </inertial>
    <visual>
      <origin
        xyz="0 0 0"
        rpy="0 0 0" />
      <geometry>
        <mesh
          filename="../meshes/base_link.STL" />
      </geometry>
      <material
        name="">
        <color
          rgba="0.79216 0.81961 0.93333 1" />
      </material>
    </visual>
    <collision>
      <origin
        xyz="0 0 0"
        rpy="0 0 0" />
      <geometry>
        <mesh
          filename="../arm/meshes/base_link.STL" />
      </geometry>
    </collision>
  </link>
  <link
    name="arm_link1">
    <inertial>
      <origin
        xyz="-0.036656 0.24877 0.0017121"
        rpy="0 0 0" />
      <mass
        value="0.69727" />
      <inertia
        ixx="0.010756"
        ixy="3.3419E-05"
        ixz="2.3151E-07"
        iyy="0.00072038"
        iyz="0.00014462"
        izz="0.01095" />
    </inertial>
    <visual>
      <origin
        xyz="0 0 0"
        rpy="0 0 0" />
      <geometry>
        <mesh
          filename="../meshes/arm_link1.STL" />
      </geometry>
      <material
        name="">
        <color
          rgba="0.79216 0.81961 0.93333 1" />
      </material>
    </visual>
    <collision>
      <origin
        xyz="0 0 0"
        rpy="0 0 0" />
      <geometry>
        <mesh
          filename="../meshes/arm_link1.STL" />
      </geometry>
    </collision>
  </link>
  <joint
    name="joint0"
    type="revolute">
    <origin
      xyz="0 0 0.011635"
      rpy="1.5708 0.70048 0.92194" />
    <parent
      link="base_link" />
    <child
      link="arm_link1" />
    <axis
      xyz="0.64459 -0.76453 0" />
    <limit
      lower="-1.57"
      upper="1.57"
      effort="0"
      velocity="12.56" />
  </joint>
  <link
    name="arm_link2">
    <inertial>
      <origin
        xyz="-0.1803 0.28553 -0.0137"
        rpy="0 0 0" />
      <mass
        value="0.44856" />
      <inertia
        ixx="0.0017557"
        ixy="4.4369E-06"
        ixz="-7.1012E-07"
        iyy="0.00042408"
        iyz="-0.00026235"
        izz="0.00175" />
    </inertial>
    <visual>
      <origin
        xyz="0 0 0"
        rpy="0 0 0" />
      <geometry>
        <mesh
          filename="../meshes/arm_link2.STL" />
      </geometry>
      <material
        name="">
        <color
          rgba="0.79216 0.81961 0.93333 1" />
      </material>
    </visual>
    <collision>
      <origin
        xyz="0 0 0"
        rpy="0 0 0" />
      <geometry>
        <mesh
          filename="../meshes/arm_link2.STL" />
      </geometry>
    </collision>
  </link>
  <joint
    name="joint1"
    type="revolute">
    <origin
      xyz="-0.1546 0.18337 0"
      rpy="0 0 -1.2473" />
    <parent
      link="arm_link1" />
    <child
      link="arm_link2" />
    <axis
      xyz="0.92979 0.36809 0" />
    <limit
      lower="-2.36"
      upper="2.36"
      effort="0"
      velocity="12.57" />
  </joint>
  <link
    name="wrist_link1">
    <inertial>
      <origin
        xyz="-0.012917 0.39657 -0.2425"
        rpy="0 0 0" />
      <mass
        value="0.28916" />
      <inertia
        ixx="0.0010542"
        ixy="-2.351E-08"
        ixz="1.1044E-13"
        iyy="0.00032126"
        iyz="7.1638E-06"
        izz="0.0011056" />
    </inertial>
    <visual>
      <origin
        xyz="0 0 0"
        rpy="0 0 0" />
      <geometry>
        <mesh
          filename="../meshes/wrist_link1.STL" />
      </geometry>
      <material
        name="">
        <color
          rgba="0.79216 0.81961 0.93333 1" />
      </material>
    </visual>
    <collision>
      <origin
        xyz="0 0 0"
        rpy="0 0 0" />
      <geometry>
        <mesh
          filename="../meshes/wrist_link1.STL" />
      </geometry>
    </collision>
  </link>
  <joint
    name="joint2"
    type="revolute">
    <origin
      xyz="0.061947 0.024524 0"
      rpy="0 1.5708 0" />
    <parent
      link="arm_link2" />
    <child
      link="wrist_link1" />
    <axis
      xyz="0 0.36809 0.92979" />
    <limit
      lower="-3.14"
      upper="3.14"
      effort="0"
      velocity="120" />
  </joint>
  <link
    name="wrist_link2">
    <inertial>
      <origin
        xyz="0.56466 0.10603 0.0069794"
        rpy="0 0 0" />
      <mass
        value="0.34435" />
      <inertia
        ixx="0.00013834"
        ixy="-1.0164E-19"
        ixz="-3.3466E-07"
        iyy="0.00063583"
        iyz="0"
        izz="0.00062808" />
    </inertial>
    <visual>
      <origin
        xyz="0 0 0"
        rpy="0 0 0" />
      <geometry>
        <mesh
          filename="../meshes/wrist_link2.STL" />
      </geometry>
      <material
        name="">
        <color
          rgba="0.79216 0.81961 0.93333 1" />
      </material>
    </visual>
    <collision>
      <origin
        xyz="0 0 0"
        rpy="0 0 0" />
      <geometry>
        <mesh
          filename="../meshes/wrist_link2.STL" />
      </geometry>
    </collision>
  </link>
  <joint
    name="joint3"
    type="revolute">
    <origin
      xyz="0 -0.0042228 -0.010667"
      rpy="-1.5708 0.25151 1.5708" />
    <parent
      link="wrist_link1" />
    <child
      link="wrist_link2" />
    <axis
      xyz="0.12512 -0.99214 0" />
    <limit
      lower="-1.57"
      upper="1.57"
      effort="0"
      velocity="7.48" />
  </joint>
  <link
    name="wrist_link3">
    <inertial>
      <origin
        xyz="0.0051806 -0.13286 0.69835"
        rpy="0 0 0" />
      <mass
        value="0.17519" />
      <inertia
        ixx="4.8698E-05"
        ixy="-1.029E-09"
        ixz="1.0133E-06"
        iyy="5.8965E-05"
        iyz="-3.161E-08"
        izz="3.4997E-05" />
    </inertial>
    <visual>
      <origin
        xyz="0 0 0"
        rpy="0 0 0" />
      <geometry>
        <mesh
          filename="../meshes/wrist_link3.STL" />
      </geometry>
      <material
        name="">
        <color
          rgba="0.79216 0.81961 0.93333 1" />
      </material>
    </visual>
    <collision>
      <origin
        xyz="0 0 0"
        rpy="0 0 0" />
      <geometry>
        <mesh
          filename="../meshes/wrist_link3.STL" />
      </geometry>
    </collision>
  </link>
  <joint
    name="joint4"
    type="revolute">
    <origin
      xyz="0.0032086 -0.025443 0"
      rpy="1.885 -1.5708 1.3008" />
    <parent
      link="wrist_link2" />
    <child
      link="wrist_link3" />
    <axis
      xyz="0 0.99193 0.12677" />
    <limit
      lower="-2.36"
      upper="2.36"
      effort="0"
      velocity="7.48" />
  </joint>
</robot>