<robot name="arm2.SLDASM">
  <link name="ground">
    <inertial>
      <origin xyz="2.139E-05 0.0017648 0.02168" rpy="0 0 0" />
      <mass value="0" />
      <inertia ixx="0" ixy="0" ixz="0" iyy="0" iyz="0" izz="0" />
    </inertial>
    <visual>
      <origin xyz="0 0 0" rpy="0 0 0" />
    </visual>
  </link>
  <link name="base_link">
    <inertial>
      <origin xyz="2.139E-05 0.0017648 0.02168" rpy="0 0 0" />
      <mass value="0.53613" />
      <inertia ixx="0.0015219" ixy="2.0239E-08" ixz="4.0918E-07" iyy="0.0013521" iyz="-2.6796E-05" izz="0.0017242" />
    </inertial>
    <visual>
      <origin xyz="0 0 0" rpy="0 0 0" />
      <geometry>
        <mesh filename="base_link.stl" />
      </geometry>
      <material name="">
        <color rgba="0.79216 0.81961 0.93333 1" />
      </material>
    </visual>
    <collision>
      <origin xyz="0 0 0" rpy="0 0 0" />
      <geometry>
        <mesh filename="base_link.stl" />
      </geometry>
    </collision>
  </link>
  <joint name="joint5" type="revolute">
    <origin xyz="0 0 0" rpy="0 0 0" />
    <parent link="ground" />
    <child link="base_link" />
    <axis xyz="0 0 1" />
    <limit lower="-4.26" upper="4.26" effort="0" velocity="12.56" />
  </joint>
  <link name="arm_link1">
    <inertial>
      <origin xyz="0.1773 -0.00039417 0.048666" rpy="0 0 0" />
      <mass value="0.5946" />
      <inertia ixx="0.00069027" ixy="3.3446E-05" ixz="-0.00014462" iyy="0.010726" iyz="-2.7335E-07" izz="0.010908" />
    </inertial>
    <visual>
      <origin xyz="0 0 0" rpy="0 0 0" />
      <geometry>
        <mesh filename="arm_link1.stl" />
      </geometry>
      <material name="">
        <color rgba="0.79216 0.81961 0.93333 1" />
      </material>
    </visual>
    <collision>
      <origin xyz="0 0 0" rpy="0 0 0" />
      <geometry>
        <mesh filename="arm_link1.stl" />
      </geometry>
    </collision>
  </link>
  <joint name="joint0" type="revolute">
    <origin xyz="0 -0.0475 0.05" rpy="-1.5708 -0.87031 0" />
    <parent link="base_link" />
    <child link="arm_link1" />
    <axis xyz="0 0 1" />
    <limit lower="-4.26" upper="4.26" effort="0" velocity="12.56" />
  </joint>
  <link name="arm_link2">
    <inertial>
      <origin xyz="0.093606 -0.00013859 -0.0074875" rpy="0 0 0" />
      <mass value="0.34589" />
      <inertia ixx="0.00038206" ixy="4.4132E-06" ixz="0.00026239" iyy="0.0017256" iyz="7.3042E-07" izz="0.0017199" />
    </inertial>
    <visual>
      <origin xyz="0 0 0" rpy="0 0 0" />
      <geometry>
        <mesh filename="arm_link2.stl" />
      </geometry>
      <material name="">
        <color rgba="0.79216 0.81961 0.93333 1" />
      </material>
    </visual>
    <collision>
      <origin xyz="0 0 0" rpy="0 0 0" />
      <geometry>
        <mesh filename="arm_link2.stl" />
      </geometry>
    </collision>
  </link>
  <joint name="joint1" type="revolute">
    <origin xyz="0.37 0 0.075" rpy="0 0 1.2473" />
    <parent link="arm_link1" />
    <child link="arm_link2" />
    <axis xyz="0 0 1" />
    <limit lower="-2.36" upper="2.36" effort="0" velocity="12.56" />
  </joint>
  <link name="wrist1">
    <inertial>
      <origin xyz="3.4694E-17 -0.00038502 0.043333" rpy="0 0 0" />
      <mass value="0.25858" />
      <inertia ixx="0.0010491" ixy="-3.8964E-19" ixz="-3.3881E-20" iyy="0.0010979" iyz="7.1638E-06" izz="0.00031674" />
    </inertial>
    <visual>
      <origin xyz="0 0 0" rpy="0 0 0" />
      <geometry>
        <mesh filename="wrist1.stl" />
      </geometry>
      <material name="">
        <color rgba="0.79216 0.81961 0.93333 1" />
      </material>
    </visual>
    <collision>
      <origin xyz="0 0 0" rpy="0 0 0" />
      <geometry>
        <mesh filename="wrist1.stl" />
      </geometry>
    </collision>
  </link>
  <joint name="joint2" type="revolute">
    <origin xyz="0.185 0 -0.035" rpy="0 1.5708 0" />
    <parent link="arm_link2" />
    <child link="wrist1" />
    <axis xyz="0 0 1" />
    <limit lower="-3.14" upper="3.14" effort="0" velocity="12.56" />
  </joint>
  <link name="hand_link">
    <inertial>
      <origin xyz="0.047132 1.3323E-15 -0.024979" rpy="0 0 0" />
      <mass value="0.34435" />
      <inertia ixx="0.00013834" ixy="-2.3717E-20" ixz="3.3466E-07" iyy="0.00063583" iyz="-1.3553E-20" izz="0.00062808" />
    </inertial>
    <visual>
      <origin xyz="0 0 0" rpy="0 0 0" />
      <geometry>
        <mesh filename="hand_link.stl" />
      </geometry>
      <material name="">
        <color rgba="0.79216 0.81961 0.93333 1" />
      </material>
    </visual>
    <collision>
      <origin xyz="0 0 0" rpy="0 0 0" />
      <geometry>
        <mesh filename="hand_link.stl" />
      </geometry>
    </collision>
  </link>
  <joint name="joint3" type="revolute">
    <origin xyz="-0.0255 0 0.125" rpy="1.5708 -1.3193 -1.5708" />
    <parent link="wrist1" />
    <child link="hand_link" />
    <axis xyz="0 0 1" />
    <limit lower="-2.36" upper="2.36" effort="0" velocity="7" />
  </joint>
  <link name="finger_link">
    <inertial>
      <origin xyz="0.077446 0.00022018 -0.023819" rpy="0 0 0" />
      <mass value="0.17519" />
      <inertia ixx="3.4998E-05" ixy="7.1554E-08" ixz="1.0133E-06" iyy="5.8966E-05" iyz="-5.8825E-10" izz="4.8699E-05" />
    </inertial>
    <visual>
      <origin xyz="0 0 0" rpy="0 0 0" />
      <geometry>
        <mesh filename="finger_link.stl" />
      </geometry>
      <material name="">
        <color rgba="0.79216 0.81961 0.93333 1" />
      </material>
    </visual>
    <collision>
      <origin xyz="0 0 0" rpy="0 0 0" />
      <geometry>
        <mesh filename="finger_link.stl" />
      </geometry>
    </collision>
  </link>
  <joint name="joint4" type="revolute">
    <origin xyz="0.1068 0 -0.047" rpy="3.1416 0 0" />
    <parent link="hand_link" />
    <child link="finger_link" />
    <axis xyz="0 0 1" />
    <limit lower="-2.36" upper="2.36" effort="0" velocity="7" />
  </joint>

    <link name="target">
      <inertial>
        <origin xyz="2.139E-05 0.0017648 0.02168" rpy="0 0 0" />
        <mass value="1" />
        <inertia ixx="1" ixy="0" ixz="0" iyy="1" iyz="0" izz="1" />
      </inertial>
      <visual>
        <geometry>
          <sphere radius="0.05"/>
        </geometry>
        <material name="yellow">
          <color rgba="1 1 0 1"/>
        </material>
      </visual>
    </link>
    <joint name="target_joint" type="floating">
      <parent link="ground" />
      <child link="target" />
      <origin xyz="0 0 0" rpy="0 0 0" />
    </joint>
</robot>