<mujoco model="arm">
    <compiler angle="radian" coordinate="local" meshdir="../meshes"/>
    <option gravity="0 0 -9.81"/>

    <asset>
        <mesh name="base_link" file="base_link.STL"/>
        <mesh name="arm_link1" file="arm_link1.STL"/>
        <mesh name="arm_link2" file="arm_link2.STL"/>
        <mesh name="wrist_link1" file="wrist_link1.STL"/>
        <mesh name="wrist_link2" file="wrist_link2.STL"/>
        <mesh name="wrist_link3" file="wrist_link3.STL"/>
    </asset>

    <worldbody>
        <!-- Base -->
        <body name="base_link" pos="0 0 0">
            <inertial pos="0.0057948 0.044245 0.0043726"
                      mass="0.63881"
                      diaginertia="0.0014518 0.0017544 0.0014944"/>

            <geom type="mesh" mesh="base_link"/>

            <!-- Joint 0 -->
            <body name="arm_link1"
                  pos="-0.036656 0.24877 0.0017121"
                  euler="0 0 0">

                <joint name="joint0"
                       type="hinge"
                       axis="0.64459 -0.76453 0"
                       range="-1.57 1.57"/>

                <inertial pos="-0.036656 0.24877 0.0017121"
                          mass="0.69727"
                          diaginertia="0.010756 0.00072038 0.01095"/>

                <geom type="mesh" mesh="arm_link1"/>

                <!-- Joint 1 -->
                <body name="arm_link2"
                      pos="-0.1546 0.18337 0"
                      euler="0 0 -1.2473">

                    <joint name="joint1"
                           type="hinge"
                           axis="0.92979 0.36809 0"
                           range="-2.36 2.36"/>

                    <inertial pos="-0.1803 0.28553 -0.0137"
                              mass="0.44856"
                              diaginertia="0.0017557 0.00042408 0.00175"/>

                    <geom type="mesh" mesh="arm_link2"/>

                    <!-- Joint 2 -->
                    <body name="wrist_link1"
                          pos="0.061947 0.024524 0"
                          euler="0 1.5708 0">

                        <joint name="joint2"
                               type="hinge"
                               axis="0 0.36809 0.92979"
                               range="-3.14 3.14"/>

                        <inertial pos="-0.012917 0.39657 -0.2425"
                                  mass="0.28916"
                                  diaginertia="0.0010542 0.00032126 0.0011056"/>

                        <geom type="mesh" mesh="wrist_link1"/>

                        <!-- Joint 3 -->
                        <body name="wrist_link2"
                              pos="0 -0.0042228 -0.010667"
                              euler="-1.5708 0.25151 1.5708">

                            <joint name="joint3"
                                   type="hinge"
                                   axis="0.12512 -0.99214 0"
                                   range="-1.57 1.57"/>

                            <inertial pos="0.56466 0.10603 0.0069794"
                                      mass="0.34435"
                                      diaginertia="0.00013834 0.00063583 0.00062808"/>

                            <geom type="mesh" mesh="wrist_link2"/>

                            <!-- Joint 4 -->
                            <body name="wrist_link3"
                                  pos="0.0032086 -0.025443 0"
                                  euler="1.885 -1.5708 1.3008">

                                <joint name="joint4"
                                       type="hinge"
                                       axis="0 0.99193 0.12677"
                                       range="-2.36 2.36"/>

                                <inertial pos="0.0051806 -0.13286 0.69835"
                                          mass="0.17519"
                                          diaginertia="4.8698e-05 5.8965e-05 3.4997e-05"/>

                                <geom type="mesh" mesh="wrist_link3"/>

                            </body>
                        </body>
                    </body>
                </body>
            </body>
        </body>
    </worldbody>
</mujoco>