<?xml version="1.0" encoding="utf-8"?>
<!-- This URDF was automatically created by SolidWorks to URDF Exporter! Originally created by Stephen Brawner (brawner@gmail.com) 
     Commit Version: 1.6.0-4-g7f85cfe  Build Version: 1.6.7995.38578
     For more information, please see http://wiki.ros.org/sw_urdf_exporter -->
<robot
  name="arm">
  <link
    name="base_link">
    <inertial>
      <origin
        xyz="0.9401 0.68999 1.6254"
        rpy="0 0 0" />
      <mass
        value="0.69063" />
      <inertia
        ixx="0.0019945"
        ixy="1.8393E-19"
        ixz="7.5492E-05"
        iyy="0.0023444"
        iyz="8.2703E-20"
        izz="0.0018065" />
    </inertial>
    <visual>
      <origin
        xyz="0 0 0"
        rpy="0 0 0" />
      <geometry>
        <mesh
          filename="../meshes/base_link.STL" />
      </geometry>
      <material
        name="">
        <color
          rgba="0.79216 0.81961 0.93333 1" />
      </material>
    </visual>
    <collision>
      <origin
        xyz="0 0 0"
        rpy="0 0 0" />
      <geometry>
        <mesh
          filename="../meshes/base_link.STL" />
      </geometry>
    </collision>
  </link>
  <link
    name="shoulder_link">
    <inertial>
      <origin
        xyz="2.3204E-13 0.19201 0.021452"
        rpy="0 0 0" />
      <mass
        value="0.52909" />
      <inertia
        ixx="0.0083742"
        ixy="3.3642E-17"
        ixz="-1.0842E-18"
        iyy="0.00067881"
        iyz="-1.2057E-06"
        izz="0.0085718" />
    </inertial>
    <visual>
      <origin
        xyz="0 0 0"
        rpy="0 0 0" />
      <geometry>
        <mesh
          filename="../meshes/shoulder_link.STL" />
      </geometry>
      <material
        name="">
        <color
          rgba="0.79216 0.81961 0.93333 1" />
      </material>
    </visual>
    <collision>
      <origin
        xyz="0 0 0"
        rpy="0 0 0" />
      <geometry>
        <mesh
          filename="../meshes/shoulder_link.STL" />
      </geometry>
    </collision>
  </link>
  <joint
    name="joint0"
    type="revolute">
    <origin
      xyz="0.94721 -1.6052 0.73686"
      rpy="1.5708 0.12264 -0.33837" />
    <parent
      link="base_link" />
    <child
      link="shoulder_link" />
    <axis
      xyz="0 0 1" />
    <limit
      lower="-1.57"
      upper="1.57"
      effort="10"
      velocity="20" />
  </joint>
  <link
    name="elbow_link">
    <inertial>
      <origin
        xyz="-0.00040915 0.060791 -0.040286"
        rpy="0 0 0" />
      <mass
        value="0.30405" />
      <inertia
        ixx="0.001555"
        ixy="8.925E-06"
        ixz="-9.6405E-08"
        iyy="0.00042147"
        iyz="1.4323E-05"
        izz="0.0014937" />
    </inertial>
    <visual>
      <origin
        xyz="0 0 0"
        rpy="0 0 0" />
      <geometry>
        <mesh
          filename="../meshes/elbow_link.STL" />
      </geometry>
      <material
        name="">
        <color
          rgba="0.79216 0.81961 0.93333 1" />
      </material>
    </visual>
    <collision>
      <origin
        xyz="0 0 0"
        rpy="0 0 0" />
      <geometry>
        <mesh
          filename="../meshes/elbow_link.STL" />
      </geometry>
    </collision>
  </link>
  <joint
    name="joint1"
    type="revolute">
    <origin
      xyz="0 0.37 0"
      rpy="0 0 -1.0913" />
    <parent
      link="shoulder_link" />
    <child
      link="elbow_link" />
    <axis
      xyz="0 0 1" />
    <limit
      lower="-2.35"
      upper="2.35"
      effort="10"
      velocity="20" />
  </joint>
  <link
    name="wrist_link1">
    <inertial>
      <origin
        xyz="8.96158792158541E-05 0.133468259482244 -0.000295926857309836"
        rpy="0 0 0" />
      <mass
        value="0.336426291824284" />
      <inertia
        ixx="0.00152881099917185"
        ixy="-2.42619306316374E-06"
        ixz="-8.92193965159205E-09"
        iyy="0.00035171540397663"
        iyz="7.04492416304363E-06"
        izz="0.00158086128910011" />
    </inertial>
    <visual>
      <origin
        xyz="0 0 0"
        rpy="0 0 0" />
      <geometry>
        <mesh
          filename="../meshes/wrist_link1.STL" />
      </geometry>
      <material
        name="">
        <color
          rgba="0.792156862745098 0.819607843137255 0.933333333333333 1" />
      </material>
    </visual>
    <collision>
      <origin
        xyz="0 0 0"
        rpy="0 0 0" />
      <geometry>
        <mesh
          filename="../meshes/wrist_link1.STL" />
      </geometry>
    </collision>
  </link>
  <joint
    name="joint3"
    type="revolute">
    <origin
      xyz="0 0.07405 -0.04106"
      rpy="0 0.87591 0" />
    <parent
      link="elbow_link" />
    <child
      link="wrist_link1" />
    <axis
      xyz="0 1 0" />
    <limit
      lower="-2.35"
      upper="2.35"
      effort="10"
      velocity="20" />
  </joint>
  <link
    name="wrist_link2">
    <inertial>
      <origin
        xyz="0.053266 1.9073E-12 2.025E-13"
        rpy="0 0 0" />
      <mass
        value="0.27316" />
      <inertia
        ixx="0.00011138"
        ixy="-2.586E-18"
        ixz="7.2972E-18"
        iyy="0.00044491"
        iyz="3.1306E-18"
        izz="0.00045088" />
    </inertial>
    <visual>
      <origin
        xyz="0 0 0"
        rpy="0 0 0" />
      <geometry>
        <mesh
          filename="../meshes/wrist_link2.STL" />
      </geometry>
      <material
        name="">
        <color
          rgba="0.79216 0.81961 0.93333 1" />
      </material>
    </visual>
    <collision>
      <origin
        xyz="0 0 0"
        rpy="0 0 0" />
      <geometry>
        <mesh
          filename="../meshes/wrist_link2.STL" />
      </geometry>
    </collision>
  </link>
  <joint
    name="joint4"
    type="revolute">
    <origin
      xyz="0 0.21394 0"
      rpy="-1.5708 0.19832 1.5708" />
    <parent
      link="wrist_link1" />
    <child
      link="wrist_link2" />
    <axis
      xyz="0 0 1" />
    <limit
      lower="-2.35"
      upper="2.35"
      effort="10"
      velocity="20" />
  </joint>
  <link
    name="wrist_link3">
    <inertial>
      <origin
        xyz="-0.00094552 -0.00036859 0.080166"
        rpy="0 0 0" />
      <mass
        value="0.16588" />
      <inertia
        ixx="4.4169E-05"
        ixy="-6.4128E-10"
        ixz="1.5924E-06"
        iyy="5.5852E-05"
        iyz="-3.2054E-08"
        izz="3.238E-05" />
    </inertial>
    <visual>
      <origin
        xyz="0 0 0"
        rpy="0 0 0" />
      <geometry>
        <mesh
          filename="../meshes/wrist_link3.STL" />
      </geometry>
      <material
        name="">
        <color
          rgba="0.79216 0.81961 0.93333 1" />
      </material>
    </visual>
    <collision>
      <origin
        xyz="0 0 0"
        rpy="0 0 0" />
      <geometry>
        <mesh
          filename="../meshes/wrist_link3.STL" />
      </geometry>
    </collision>
  </link>
  <joint
    name="joint"
    type="revolute">
    <origin
      xyz="0.102 0 0"
      rpy="2.6957 -1.5708 0" />
    <parent
      link="wrist_link2" />
    <child
      link="wrist_link3" />
    <axis
      xyz="1 0 0" />
    <limit
      lower="-2.35"
      upper="2.35"
      effort="10"
      velocity="20" />
  </joint>
</robot>